loading annotations into memory...
Done (t=26.44s)
creating index...
index created!
Train Image Count: 280741
Train Class Count: 2
  0. BG
  1. building
loading annotations into memory...
Done (t=7.02s)
creating index...
index created!
Val Image Count: 60317
Val Class Count: 2
  0. BG
  1. building
logs/2024-10-22_15-40-00/maskrcnn_resnet50_fpn_v2.pth
/home/your_email/iptu/samples/mapping/main.py:241: FutureWarning: `torch.cuda.amp.GradScaler(args...)` is deprecated. Please use `torch.amp.GradScaler('cuda', args...)` instead.
  scaler = torch.cuda.amp.GradScaler() if device.type == 'cuda' and use_scaler else None
Epochs:   0%|                                                                                                                       | 0/40 [00:00<?, ?it/s]
GPU disponível. Treinamento iniciará na GPU.
Traceback (most recent call last):                                                                                               | 0/70186 [00:00<?, ?it/s]
  File "/home/your_email/iptu/samples/mapping/main.py", line 347, in <module>
    main(dataset_dir=dataset_dir, epochs=epochs, size=size, class_names=class_names)
  File "/home/your_email/iptu/samples/mapping/main.py", line 323, in main
    train_loop(model=model,
  File "/home/your_email/iptu/samples/mapping/main.py", line 247, in train_loop
    train_loss = run_epoch(model, train_dataloader, optimizer, lr_scheduler, device, scaler, epoch, is_training=True)
  File "/home/your_email/iptu/samples/mapping/main.py", line 160, in run_epoch
    for batch_id, (inputs, targets) in enumerate(dataloader):
  File "/home/your_email/miniconda/envs/iptu310/lib/python3.10/site-packages/torch/utils/data/dataloader.py", line 701, in __next__
    data = self._next_data()
  File "/home/your_email/miniconda/envs/iptu310/lib/python3.10/site-packages/torch/utils/data/dataloader.py", line 1465, in _next_data
    return self._process_data(data)
  File "/home/your_email/miniconda/envs/iptu310/lib/python3.10/site-packages/torch/utils/data/dataloader.py", line 1491, in _process_data
    data.reraise()
  File "/home/your_email/miniconda/envs/iptu310/lib/python3.10/site-packages/torch/_utils.py", line 715, in reraise
    raise exception
IndexError: Caught IndexError in DataLoader worker process 0.
Original Traceback (most recent call last):
  File "/home/your_email/miniconda/envs/iptu310/lib/python3.10/site-packages/torch/utils/data/_utils/worker.py", line 351, in _worker_loop
    data = fetcher.fetch(index)  # type: ignore[possibly-undefined]
  File "/home/your_email/miniconda/envs/iptu310/lib/python3.10/site-packages/torch/utils/data/_utils/fetch.py", line 52, in fetch
    data = [self.dataset[idx] for idx in possibly_batched_index]
  File "/home/your_email/miniconda/envs/iptu310/lib/python3.10/site-packages/torch/utils/data/_utils/fetch.py", line 52, in <listcomp>
    data = [self.dataset[idx] for idx in possibly_batched_index]
  File "/home/your_email/iptu/samples/mapping/dataloader.py", line 36, in __getitem__
    image, targets = self.transform(image, targets)
  File "/home/your_email/miniconda/envs/iptu310/lib/python3.10/site-packages/torch/nn/modules/module.py", line 1736, in _wrapped_call_impl
    return self._call_impl(*args, **kwargs)
  File "/home/your_email/miniconda/envs/iptu310/lib/python3.10/site-packages/torch/nn/modules/module.py", line 1747, in _call_impl
    return forward_call(*args, **kwargs)
  File "/home/your_email/miniconda/envs/iptu310/lib/python3.10/site-packages/torchvision/transforms/v2/_container.py", line 51, in forward
    outputs = transform(*inputs)
  File "/home/your_email/miniconda/envs/iptu310/lib/python3.10/site-packages/torch/nn/modules/module.py", line 1736, in _wrapped_call_impl
    return self._call_impl(*args, **kwargs)
  File "/home/your_email/miniconda/envs/iptu310/lib/python3.10/site-packages/torch/nn/modules/module.py", line 1747, in _call_impl
    return forward_call(*args, **kwargs)
  File "/home/your_email/miniconda/envs/iptu310/lib/python3.10/site-packages/torchvision/transforms/v2/_container.py", line 51, in forward
    outputs = transform(*inputs)
  File "/home/your_email/miniconda/envs/iptu310/lib/python3.10/site-packages/torch/nn/modules/module.py", line 1736, in _wrapped_call_impl
    return self._call_impl(*args, **kwargs)
  File "/home/your_email/miniconda/envs/iptu310/lib/python3.10/site-packages/torch/nn/modules/module.py", line 1747, in _call_impl
    return forward_call(*args, **kwargs)
  File "/home/your_email/miniconda/envs/iptu310/lib/python3.10/site-packages/torchvision/transforms/v2/_misc.py", line 435, in forward
    flat_outputs = [self._transform(inpt, params) for inpt in flat_inputs]
  File "/home/your_email/miniconda/envs/iptu310/lib/python3.10/site-packages/torchvision/transforms/v2/_misc.py", line 435, in <listcomp>
    flat_outputs = [self._transform(inpt, params) for inpt in flat_inputs]
  File "/home/your_email/miniconda/envs/iptu310/lib/python3.10/site-packages/torchvision/transforms/v2/_misc.py", line 446, in _transform
    output = inpt[params["valid"]]
  File "/home/your_email/miniconda/envs/iptu310/lib/python3.10/site-packages/torchvision/tv_tensors/_tv_tensor.py", line 77, in __torch_function__
    output = func(*args, **kwargs or dict())
IndexError: The shape of the mask [17] at index 0 does not match the shape of the indexed tensor [4, 300, 300] at index 0
