loading annotations into memory...
Done (t=26.57s)
creating index...
index created!
Train Image Count: 280529
Train Class Count: 2
  0. BG
  1. building
loading annotations into memory...
Done (t=7.26s)
creating index...
index created!
Val Image Count: 60286
Val Class Count: 2
  0. BG
  1. building
logs/2024-10-22_19-13-56/maskrcnn_resnet50_fpn_v2.pth
/home/your_email/iptu/samples/mapping/main.py:241: FutureWarning: `torch.cuda.amp.GradScaler(args...)` is deprecated. Please use `torch.amp.GradScaler('cuda', args...)` instead.
  scaler = torch.cuda.amp.GradScaler() if device.type == 'cuda' and use_scaler else None
Epochs:   0%|                                                                                                                   | 0/40 [00:06<?, ?it/s]
GPU disponível. Treinamento iniciará na GPU.
Traceback (most recent call last):                                            | 10/70186 [00:06<10:16:08,  1.90it/s, loss=1.86, avg_loss=2.04, lr=2e-5]
  File "/home/your_email/iptu/samples/mapping/main.py", line 348, in <module>
    # if args.class_names:
  File "/home/your_email/iptu/samples/mapping/main.py", line 324, in main
    print(checkpoint_path)
  File "/home/your_email/iptu/samples/mapping/main.py", line 247, in train_loop
    for epoch in tqdm(range(epochs), desc="Epochs"):
  File "/home/your_email/iptu/samples/mapping/main.py", line 160, in run_epoch
    for batch_id, (inputs, targets) in enumerate(dataloader):
  File "/home/your_email/miniconda/envs/iptu310/lib/python3.10/site-packages/torch/utils/data/dataloader.py", line 701, in __next__
    data = self._next_data()
  File "/home/your_email/miniconda/envs/iptu310/lib/python3.10/site-packages/torch/utils/data/dataloader.py", line 1465, in _next_data
    return self._process_data(data)
  File "/home/your_email/miniconda/envs/iptu310/lib/python3.10/site-packages/torch/utils/data/dataloader.py", line 1491, in _process_data
    data.reraise()
  File "/home/your_email/miniconda/envs/iptu310/lib/python3.10/site-packages/torch/_utils.py", line 715, in reraise
    raise exception
IndexError: Caught IndexError in DataLoader worker process 0.
Original Traceback (most recent call last):
  File "/home/your_email/miniconda/envs/iptu310/lib/python3.10/site-packages/torch/utils/data/_utils/worker.py", line 351, in _worker_loop
    data = fetcher.fetch(index)  # type: ignore[possibly-undefined]
  File "/home/your_email/miniconda/envs/iptu310/lib/python3.10/site-packages/torch/utils/data/_utils/fetch.py", line 52, in fetch
    data = [self.dataset[idx] for idx in possibly_batched_index]
  File "/home/your_email/miniconda/envs/iptu310/lib/python3.10/site-packages/torch/utils/data/_utils/fetch.py", line 52, in <listcomp>
    data = [self.dataset[idx] for idx in possibly_batched_index]
  File "/home/your_email/iptu/samples/mapping/dataloader.py", line 32, in __getitem__
    image, targets = self._load_image_and_target(image_id)
  File "/home/your_email/iptu/samples/mapping/dataloader.py", line 56, in _load_image_and_target
    image_info = self.dataset.image_info[image_id-1]
IndexError: list index out of range
